src.biopharma timed out after 15.0 minutes.



src.pharmtech_new timed out after 15.0 minutes.

src.genenews timed out after 15.0 minutes.

Error in src.pharmtech_new:
Traceback (most recent call last):
  File "C:\Users\AnjaliRani\AppData\Local\Programs\Python\Python313\Lib\site-packages\urllib3\connectionpool.py", line 534, in _make_request
    response = conn.getresponse()
  File "C:\Users\AnjaliRani\AppData\Local\Programs\Python\Python313\Lib\site-packages\urllib3\connection.py", line 565, in getresponse
    httplib_response = super().getresponse()
  File "C:\Users\AnjaliRani\AppData\Local\Programs\Python\Python313\Lib\http\client.py", line 1430, in getresponse
    response.begin()
    ~~~~~~~~~~~~~~^^
  File "C:\Users\AnjaliRani\AppData\Local\Programs\Python\Python313\Lib\http\client.py", line 331, in begin
    version, status, reason = self._read_status()
                              ~~~~~~~~~~~~~~~~~^^
  File "C:\Users\AnjaliRani\AppData\Local\Programs\Python\Python313\Lib\http\client.py", line 292, in _read_status
    line = str(self.fp.readline(_MAXLINE + 1), "iso-8859-1")
               ~~~~~~~~~~~~~~~~^^^^^^^^^^^^^^
  File "C:\Users\AnjaliRani\AppData\Local\Programs\Python\Python313\Lib\socket.py", line 719, in readinto
    return self._sock.recv_into(b)
           ~~~~~~~~~~~~~~~~~~~~^^^
TimeoutError: timed out

The above exception was the direct cause of the following exception:

Traceback (most recent call last):
  File "C:\Piramel_Application\src\driver.py", line 21, in target
    scraper.main()
    ~~~~~~~~~~~~^^
  File "C:\Piramel_Application\src\pharmtech_new.py", line 121, in main
    url_entries = get_urls_from_sitemap(page)
  File "C:\Piramel_Application\src\pharmtech_new.py", line 28, in get_urls_from_sitemap
    driver.get(url)
    ~~~~~~~~~~^^^^^
  File "C:\Users\AnjaliRani\AppData\Local\Programs\Python\Python313\Lib\site-packages\selenium\webdriver\remote\webdriver.py", line 483, in get
    self.execute(Command.GET, {"url": url})
    ~~~~~~~~~~~~^^^^^^^^^^^^^^^^^^^^^^^^^^^
  File "C:\Users\AnjaliRani\AppData\Local\Programs\Python\Python313\Lib\site-packages\selenium\webdriver\remote\webdriver.py", line 455, in execute
    response = cast(RemoteConnection, self.command_executor).execute(driver_command, params)
  File "C:\Users\AnjaliRani\AppData\Local\Programs\Python\Python313\Lib\site-packages\selenium\webdriver\remote\remote_connection.py", line 406, in execute
    return self._request(command_info[0], url, body=data)
           ~~~~~~~~~~~~~^^^^^^^^^^^^^^^^^^^^^^^^^^^^^^^^^
  File "C:\Users\AnjaliRani\AppData\Local\Programs\Python\Python313\Lib\site-packages\selenium\webdriver\remote\remote_connection.py", line 430, in _request
    response = self._conn.request(method, url, body=body, headers=headers, timeout=self._client_config.timeout)
  File "C:\Users\AnjaliRani\AppData\Local\Programs\Python\Python313\Lib\site-packages\urllib3\_request_methods.py", line 143, in request
    return self.request_encode_body(
           ~~~~~~~~~~~~~~~~~~~~~~~~^
        method, url, fields=fields, headers=headers, **urlopen_kw
        ^^^^^^^^^^^^^^^^^^^^^^^^^^^^^^^^^^^^^^^^^^^^^^^^^^^^^^^^^
    )
    ^
  File "C:\Users\AnjaliRani\AppData\Local\Programs\Python\Python313\Lib\site-packages\urllib3\_request_methods.py", line 278, in request_encode_body
    return self.urlopen(method, url, **extra_kw)
           ~~~~~~~~~~~~^^^^^^^^^^^^^^^^^^^^^^^^^
  File "C:\Users\AnjaliRani\AppData\Local\Programs\Python\Python313\Lib\site-packages\urllib3\poolmanager.py", line 459, in urlopen
    response = conn.urlopen(method, u.request_uri, **kw)
  File "C:\Users\AnjaliRani\AppData\Local\Programs\Python\Python313\Lib\site-packages\urllib3\connectionpool.py", line 841, in urlopen
    retries = retries.increment(
        method, url, error=new_e, _pool=self, _stacktrace=sys.exc_info()[2]
    )
  File "C:\Users\AnjaliRani\AppData\Local\Programs\Python\Python313\Lib\site-packages\urllib3\util\retry.py", line 474, in increment
    raise reraise(type(error), error, _stacktrace)
          ~~~~~~~^^^^^^^^^^^^^^^^^^^^^^^^^^^^^^^^^
  File "C:\Users\AnjaliRani\AppData\Local\Programs\Python\Python313\Lib\site-packages\urllib3\util\util.py", line 39, in reraise
    raise value
  File "C:\Users\AnjaliRani\AppData\Local\Programs\Python\Python313\Lib\site-packages\urllib3\connectionpool.py", line 787, in urlopen
    response = self._make_request(
        conn,
    ...<10 lines>...
        **response_kw,
    )
  File "C:\Users\AnjaliRani\AppData\Local\Programs\Python\Python313\Lib\site-packages\urllib3\connectionpool.py", line 536, in _make_request
    self._raise_timeout(err=e, url=url, timeout_value=read_timeout)
    ~~~~~~~~~~~~~~~~~~~^^^^^^^^^^^^^^^^^^^^^^^^^^^^^^^^^^^^^^^^^^^^
  File "C:\Users\AnjaliRani\AppData\Local\Programs\Python\Python313\Lib\site-packages\urllib3\connectionpool.py", line 367, in _raise_timeout
    raise ReadTimeoutError(
        self, url, f"Read timed out. (read timeout={timeout_value})"
    ) from err
urllib3.exceptions.ReadTimeoutError: HTTPConnectionPool(host='localhost', port=59288): Read timed out. (read timeout=120)


